Exception in thread Thread-2:
Traceback (most recent call last):
  File "threading.pyc", line 810, in __bootstrap_inner
  File "threading.pyc", line 763, in run
  File "server.py", line 81, in tcplink
  File "Tkinter.pyc", line 3104, in insert
TclError: invalid command name ".35846024.35846184.35846984"

